Workbook

Sheet Summary
A1: Sri Lankan Tamil Inscriptions, Archaeology, Hero Stones & Rock Art: Bibliography
A2: Books, research papers, newspaper and magazine articles, 1996-2026 (plus key earlier references). Compiled 2026-10-14. Counts below are live formulas over the 'All Records' sheet.
A3: Keywords: கல்வெட்டு, கல்வெட்டுகள், தமிழ், தொல்லியல், நடுகல், பாறை ஓவியம் / inscription, epigraphy, Tamil, archaeology, hero stone, rock art, Brahmi, coins
A5: Category | B5: Records | C5: Within 1996-2026
A6: Books | B6: =COUNTIF('All Records'!$B$2:$B$465,A6) | C6: =COUNTIFS('All Records'!$B$2:$B$465,A6,'All Records'!$L$2:$L$465,"Yes")
A7: Research Papers | B7: =COUNTIF('All Records'!$B$2:$B$465,A7) | C7: =COUNTIFS('All Records'!$B$2:$B$465,A7,'All Records'!$L$2:$L$465,"Yes")
A8: Newspaper Articles | B8: =COUNTIF('All Records'!$B$2:$B$465,A8) | C8: =COUNTIFS('All Records'!$B$2:$B$465,A8,'All Records'!$L$2:$L$465,"Yes")
A9: Magazines/Journals | B9: =COUNTIF('All Records'!$B$2:$B$465,A9) | C9: =COUNTIFS('All Records'!$B$2:$B$465,A9,'All Records'!$L$2:$L$465,"Yes")
A10: Web Articles | B10: =COUNTIF('All Records'!$B$2:$B$465,A10) | C10: =COUNTIFS('All Records'!$B$2:$B$465,A10,'All Records'!$L$2:$L$465,"Yes")
A11: Total | B11: =SUM(B6:B10) | C11: =SUM(C6:C10)
A13: Theme | B13: Records
A14: Inscriptions / கல்வெட்டு | B14: =COUNTIF('All Records'!$J$2:$J$465,"*"&A14&"*")
A15: Brahmi / பிராமி | B15: =COUNTIF('All Records'!$J$2:$J$465,"*"&A15&"*")
A16: Archaeology / தொல்லியல் | B16: =COUNTIF('All Records'!$J$2:$J$465,"*"&A16&"*")
A17: Hero stones / நடுகல் | B17: =COUNTIF('All Records'!$J$2:$J$465,"*"&A17&"*")
A18: Rock art / பாறை ஓவியம் | B18: =COUNTIF('All Records'!$J$2:$J$465,"*"&A18&"*")
A19: Coins / நாணயம் | B19: =COUNTIF('All Records'!$J$2:$J$465,"*"&A19&"*")
A20: A record can carry several themes, so theme counts add up to more than the total.
A22: Period | B22: Books | C22: Research Papers | D22: Newspaper Articles | E22: Magazines/Journals | F22: Web Articles | G22: All
A23: 1996-2000 | B23: =SUMPRODUCT(('All Records'!$B$2:$B$465="Books")*(IFERROR(VALUE(LEFT('All Records'!$C$2:$C$465,4)),0)>=1996)*(IFERROR(VALUE(LEFT('All Records'!$C$2:$C$465,4)),0)<=2000)) | C23: =SUMPRODUCT(('All Records'!$B$2:$B$465="Research Papers")*(IFERROR(VALUE(LEFT('All Records'!$C$2:$C$465,4)),0)>=1996)*(IFERROR(VALUE(LEFT('All Records'!$C$2:$C$465,4)),0)<=2000)) | D23: =SUMPRODUCT(('All Records'!$B$2:$B$465="Newspaper Articles")*(IFERROR(VALUE(LEFT('All Records'!$C$2:$C$465,4)),0)>=1996)*(IFERROR(VALUE(LEFT('All Records'!$C$2:$C$465,4)),0)<=2000)) | E23: =SUMPRODUCT(('All Records'!$B$2:$B$465="Magazines/Journals")*(IFERROR(VALUE(LEFT('All Records'!$C$2:$C$465,4)),0)>=1996)*(IFERROR(VALUE(LEFT('All Records'!$C$2:$C$465,4)),0)<=2000)) | F23: =SUMPRODUCT(('All Records'!$B$2:$B$465="Web Articles")*(IFERROR(VALUE(LEFT('All Records'!$C$2:$C$465,4)),0)>=1996)*(IFERROR(VALUE(LEFT('All Records'!$C$2:$C$465,4)),0)<=2000)) | G23: =SUM(B23:F23)
A24: 2001-2005 | B24: =SUMPRODUCT(('All Records'!$B$2:$B$465="Books")*(IFERROR(VALUE(LEFT('All Records'!$C$2:$C$465,4)),0)>=2001)*(IFERROR(VALUE(LEFT('All Records'!$C$2:$C$465,4)),0)<=2005)) | C24: =SUMPRODUCT(('All Records'!$B$2:$B$465="Research Papers")*(IFERROR(VALUE(LEFT('All Records'!$C$2:$C$465,4)),0)>=2001)*(IFERROR(VALUE(LEFT('All Records'!$C$2:$C$465,4)),0)<=2005)) | D24: =SUMPRODUCT(('All Records'!$B$2:$B$465="Newspaper Articles")*(IFERROR(VALUE(LEFT('All Records'!$C$2:$C$465,4)),0)>=2001)*(IFERROR(VALUE(LEFT('All Records'!$C$2:$C$465,4)),0)<=2005)) | E24: =SUMPRODUCT(('All Records'!$B$2:$B$465="Magazines/Journals")*(IFERROR(VALUE(LEFT('All Records'!$C$2:$C$465,4)),0)>=2001)*(IFERROR(VALUE(LEFT('All Records'!$C$2:$C$465,4)),0)<=2005)) | F24: =SUMPRODUCT(('All Records'!$B$2:$B$465="Web Articles")*(IFERROR(VALUE(LEFT('All Records'!$C$2:$C$465,4)),0)>=2001)*(IFERROR(VALUE(LEFT('All Records'!$C$2:$C$465,4)),0)<=2005)) | G24: =SUM(B24:F24)
A25: 2006-2010 | B25: =SUMPRODUCT(('All Records'!$B$2:$B$465="Books")*(IFERROR(VALUE(LEFT('All Records'!$C$2:$C$465,4)),0)>=2006)*(IFERROR(VALUE(LEFT('All Records'!$C$2:$C$465,4)),0)<=2010)) | C25: =SUMPRODUCT(('All Records'!$B$2:$B$465="Research Papers")*(IFERROR(VALUE(LEFT('All Records'!$C$2:$C$465,4)),0)>=2006)*(IFERROR(VALUE(LEFT('All Records'!$C$2:$C$465,4)),0)<=2010)) | D25: =SUMPRODUCT(('All Records'!$B$2:$B$465="Newspaper Articles")*(IFERROR(VALUE(LEFT('All Records'!$C$2:$C$465,4)),0)>=2006)*(IFERROR(VALUE(LEFT('All Records'!$C$2:$C$465,4)),0)<=2010)) | E25: =SUMPRODUCT(('All Records'!$B$2:$B$465="Magazines/Journals")*(IFERROR(VALUE(LEFT('All Records'!$C$2:$C$465,4)),0)>=2006)*(IFERROR(VALUE(LEFT('All Records'!$C$2:$C$465,4)),0)<=2010)) | F25: =SUMPRODUCT(('All Records'!$B$2:$B$465="Web Articles")*(IFERROR(VALUE(LEFT('All Records'!$C$2:$C$465,4)),0)>=2006)*(IFERROR(VALUE(LEFT('All Records'!$C$2:$C$465,4)),0)<=2010)) | G25: =SUM(B25:F25)
A26: 2011-2015 | B26: =SUMPRODUCT(('All Records'!$B$2:$B$465="Books")*(IFERROR(VALUE(LEFT('All Records'!$C$2:$C$465,4)),0)>=2011)*(IFERROR(VALUE(LEFT('All Records'!$C$2:$C$465,4)),0)<=2015)) | C26: =SUMPRODUCT(('All Records'!$B$2:$B$465="Research Papers")*(IFERROR(VALUE(LEFT('All Records'!$C$2:$C$465,4)),0)>=2011)*(IFERROR(VALUE(LEFT('All Records'!$C$2:$C$465,4)),0)<=2015)) | D26: =SUMPRODUCT(('All Records'!$B$2:$B$465="Newspaper Articles")*(IFERROR(VALUE(LEFT('All Records'!$C$2:$C$465,4)),0)>=2011)*(IFERROR(VALUE(LEFT('All Records'!$C$2:$C$465,4)),0)<=2015)) | E26: =SUMPRODUCT(('All Records'!$B$2:$B$465="Magazines/Journals")*(IFERROR(VALUE(LEFT('All Records'!$C$2:$C$465,4)),0)>=2011)*(IFERROR(VALUE(LEFT('All Records'!$C$2:$C$465,4)),0)<=2015)) | F26: =SUMPRODUCT(('All Records'!$B$2:$B$465="Web Articles")*(IFERROR(VALUE(LEFT('All Records'!$C$2:$C$465,4)),0)>=2011)*(IFERROR(VALUE(LEFT('All Records'!$C$2:$C$465,4)),0)<=2015)) | G26: =SUM(B26:F26)
A27: 2016-2020 | B27: =SUMPRODUCT(('All Records'!$B$2:$B$465="Books")*(IFERROR(VALUE(LEFT('All Records'!$C$2:$C$465,4)),0)>=2016)*(IFERROR(VALUE(LEFT('All Records'!$C$2:$C$465,4)),0)<=2020)) | C27: =SUMPRODUCT(('All Records'!$B$2:$B$465="Research Papers")*(IFERROR(VALUE(LEFT('All Records'!$C$2:$C$465,4)),0)>=2016)*(IFERROR(VALUE(LEFT('All Records'!$C$2:$C$465,4)),0)<=2020)) | D27: =SUMPRODUCT(('All Records'!$B$2:$B$465="Newspaper Articles")*(IFERROR(VALUE(LEFT('All Records'!$C$2:$C$465,4)),0)>=2016)*(IFERROR(VALUE(LEFT('All Records'!$C$2:$C$465,4)),0)<=2020)) | E27: =SUMPRODUCT(('All Records'!$B$2:$B$465="Magazines/Journals")*(IFERROR(VALUE(LEFT('All Records'!$C$2:$C$465,4)),0)>=2016)*(IFERROR(VALUE(LEFT('All Records'!$C$2:$C$465,4)),0)<=2020)) | F27: =SUMPRODUCT(('All Records'!$B$2:$B$465="Web Articles")*(IFERROR(VALUE(LEFT('All Records'!$C$2:$C$465,4)),0)>=2016)*(IFERROR(VALUE(LEFT('All Records'!$C$2:$C$465,4)),0)<=2020)) | G27: =SUM(B27:F27)
A28: 2021-2026 | B28: =SUMPRODUCT(('All Records'!$B$2:$B$465="Books")*(IFERROR(VALUE(LEFT('All Records'!$C$2:$C$465,4)),0)>=2021)*(IFERROR(VALUE(LEFT('All Records'!$C$2:$C$465,4)),0)<=2026)) | C28: =SUMPRODUCT(('All Records'!$B$2:$B$465="Research Papers")*(IFERROR(VALUE(LEFT('All Records'!$C$2:$C$465,4)),0)>=2021)*(IFERROR(VALUE(LEFT('All Records'!$C$2:$C$465,4)),0)<=2026)) | D28: =SUMPRODUCT(('All Records'!$B$2:$B$465="Newspaper Articles")*(IFERROR(VALUE(LEFT('All Records'!$C$2:$C$465,4)),0)>=2021)*(IFERROR(VALUE(LEFT('All Records'!$C$2:$C$465,4)),0)<=2026)) | E28: =SUMPRODUCT(('All Records'!$B$2:$B$465="Magazines/Journals")*(IFERROR(VALUE(LEFT('All Records'!$C$2:$C$465,4)),0)>=2021)*(IFERROR(VALUE(LEFT('All Records'!$C$2:$C$465,4)),0)<=2026)) | F28: =SUMPRODUCT(('All Records'!$B$2:$B$465="Web Articles")*(IFERROR(VALUE(LEFT('All Records'!$C$2:$C$465,4)),0)>=2021)*(IFERROR(VALUE(LEFT('All Records'!$C$2:$C$465,4)),0)<=2026)) | G28: =SUM(B28:F28)
A29: Records with no year yet are counted in the category totals but not in this period table.

Sheet Books
A1: ID | B1: Year | C1: Date | D1: Title | E1: Author / Editor | F1: Publisher / Source | G1: Type | H1: Language | I1: Themes | J1: Keywords | K1: Within 1996-2026 | L1: Notes | M1: URL
A2: BK-0001 | B2: 2026 | C2: 2026-02-15 | D2: Religion, Gender, and Politics in Medieval Sri Lanka: The Reconstruction of Buddhist Kingship, ca. 1070–1215 | E2: Bruno M. Shirley | G2: Book | H2: English | K2: Yes | L2: OpenAlex query: Tamil Brahmi Sri Lanka. Auto-collected 2026-10-14 (openalex); review. | M2: https://doi.org/10.17302/kshl2567
A3: BK-0002 | B3: 2026 | C3: 2026-04-11 | D3: Glimpses of an Ancient Civilisation: Society and Culture in Jaffna (300 BC to AD 500) | E3: S. Pathmanathan | G3: Book | H3: English | I3: Brahmi / பிராமி; Archaeology / தொல்லியல்; Coins / நாணயம் | J3: Tamil-Brahmi; Vallipuram gold plate; Roman coins; archaeology | K3: Yes | L3: Launched 11 Apr 2026 | M3: https://www.tamilguardian.com/content/prof-pathmanathans-new-book-sheds-light-early-jaffna-civilisation
A4: BK-0003 | B4: 2025 | D4: இலங்கையின் பிராமி மற்றும் சிங்களக் கல்வெட்டுகளில் தமிழர் (Tamils in the Brahmi and Sinhala Inscriptions of Sri Lanka) | E4: N. K. S. Thiruchelvam | F4: Ezhuna | G4: Book | H4: Tamil | I4: Inscriptions / கல்வெட்டு; Brahmi / பிராமி | J4: Brahmi; கல்வெட்டு; Tamils | K4: Yes | L4: Book launch 26 Jul 2025, Trincomalee | M4: https://www.ezhunaonline.com/books/tamils-in-the-inscriptions-of-brahmi-and-sinhala/
A5: BK-0004 | B5: 2022 | D5: Ancient Sri Lanka: Glimpses of the Past | E5: K. Indrapala | F5: Ohm Books Publishing | G5: Book | H5: English | I5: Archaeology / தொல்லியல் | J5: archaeology; history | K5: Yes | M5: https://en.wikipedia.org/wiki/K._Indrapala
A6: BK-0005 | B6: 2017 | D6: இலங்கைத் தமிழர்: ஒரு சுருக்க வரலாறு (Sri Lankan Tamils: A Brief History) | E6: P. Pushparatnam | F6: Tamil Education Service, Switzerland | G6: Book | H6: Tamil | I6: Archaeology / தொல்லியல் | J6: history; archaeology | K6: Yes | L6: Noolaham No. 75615; 248 pp. | M6: https://noolaham.org/wiki/index.php/இலங்கைத்_தமிழர்:_ஒரு_சுருக்க_வரலாறு
A7: BK-0006 | B7: 2017 | D7: ஈழத் தமிழர் மரபுரிமை அடையாளங்கள் (Heritage Symbols of Eelam Tamils) | E7: P. Pushparatnam | F7: Tamil Education Service, Switzerland | G7: Book | H7: Tamil | I7: Archaeology / தொல்லியல் | J7: heritage; தொல்லியல் | K7: Yes | L7: Noolaham No. 75614; 240 pp. | M7: https://noolaham.org/wiki/index.php/ஈழத்_தமிழர்_மரபுரிமை_அடையாளங்கள்
A8: BK-0007 | B8: 2017 | C8: 2017-06-06 | D8: Sri Lanka at the Crossroads of History | E8: Coningham, R.A.E., Manuel, M.J., Davis, C.E., Gunawardhana, P. | F8: Noolaham digital library | G8: Book | H8: English | I8: Archaeology / தொல்லியல் | J8: history; archaeology | K8: Yes | L8: Details to verify | M8: https://noolaham.net/project/810/80954/80954.pdf
A9: BK-0008 | B9: 2014 | D9: Collection of Historical Articles of Prof. V. Sivasamy | E9: K. Arunthavarajah (ed.) | F9: Anchu Publication, Nallur | G9: Edited volume | H9: Tamil | I9: Inscriptions / கல்வெட்டு | J9: history; epigraphy | K9: Yes | M9: https://www.his.jfn.ac.lk/index.php/profkarunthavarajah/
A10: BK-0009 | B10: 2014 | C10: 2014-02-17 | D10: இலங்கையில் தமிழர்: ஓர் இனக்குழு ஆக்கம் பெற்ற வரலாறு | E10: K. Indrapala (Tamil edition) | F10: Wikipedia (ta) | G10: Book | H10: Tamil | I10: Inscriptions / கல்வெட்டு; Brahmi / பிராமி | J10: Brahmi; inscriptions; ethnic history | K10: Yes | L10: Tamil version of Evolution of an Ethnic Identity; details to verify (Noolaham rate-limited) | M10: https://noolaham.org/wiki/index.php/இலங்கையில்_தமிழர்:_ஓர்_இனக்குழு_ஆக்கம்_பெற்ற_வரலாறு
A11: BK-0010 | B11: 2013 | D11: நல்லூர் இராஜதானியும் யாழ்ப்பாணக் கோட்டையும் - மீள்வாசிப்பு | E11: P. Pushparatnam | F11: Colombo Tamil Sangam | G11: Book | H11: Tamil | I11: Archaeology / தொல்லியல் | J11: தொல்லியல்; Nallur; Jaffna Fort | K11: Yes | L11: Noolaham No. 97925; 48 pp. | M11: https://noolaham.org/wiki/index.php/நல்லூர்_இராஜதானியும்_யாழ்ப்பாணக்_கோட்டையும்_-_மீள்வாசிப்பு
A12: BK-0011 | B12: 2012 | D12: Life Style of Jaffna | E12: K. Arunthavarajah (managing ed.) | F12: Department of History, University of Jaffna, with Veerakesari | G12: Edited volume | H12: English | I12: Archaeology / தொல்லியல் | J12: material culture; heritage | K12: Yes | M12: https://www.his.jfn.ac.lk/index.php/profkarunthavarajah/
A13: BK-0012 | B13: 2010 | D13: Spolia Zeylanica Vol. 47: Tamil Inscriptions in the Colombo National Museum | E13: Department of National Museums | F13: Department of National Museums, Colombo | G13: Book | H13: English | I13: Inscriptions / கல்வெட்டு | J13: Tamil inscriptions; museum catalogue | K13: Yes | L13: ISBN 9789555780278 | M13: https://opac.busl.ac.lk/bib/14671
A14: BK-0013 | B14: 2008 | D14: Rock and Wall Paintings of Sri Lanka (facsimile edition) | E14: Senaka Bandaranayake | F14: Stamford Lake | G14: Book | H14: English | I14: Rock art / பாறை ஓவியம் | J14: பாறை ஓவியம்; rock art; wall paintings | K14: Yes | L14: Publisher to verify | M14: https://www.sundaytimes.lk/080504/Plus/plus000025.html
A15: BK-0014 | B15: 2006 | D15: Ilankait Tamilc Cacanankal c. AD 800-1300 (Tamil Inscriptions of Sri Lanka) | E15: S. Pathmanathan | F15: Department of Hindu Religious and Cultural Affairs | G15: Book | H15: Tamil | I15: Inscriptions / கல்வெட்டு | J15: கல்வெட்டு; inscriptions corpus | K15: Yes | L15: Same as entry from Wikipedia; fuller title | M15: https://jfn.ac.lk/prof-s-pathmanathan/
A16: BK-0015 | B16: 2006 | D16: இலங்கைத் தமிழ்ச் சாசனங்கள் (Tamil Inscriptions in Sri Lanka) | E16: S. Pathmanathan | F16: Department of Hindu Religious & Cultural Affairs, Colombo | G16: Book | H16: Tamil | I16: Inscriptions / கல்வெட்டு | J16: inscriptions; கல்வெட்டு | K16: Yes | M16: https://en.wikipedia.org/wiki/S._Pathmanathan
A17: BK-0016 | B17: 2005 | D17: Hindu Encyclopaedia (Tamil), Parts I-IX (1992-2008) | E17: S. Pathmanathan (ed.-in-chief) | F17: Department of Hindu Religious and Cultural Affairs | G17: Encyclopaedia | H17: Tamil | J17: encyclopaedia; temples | K17: Yes | L17: Parts: III 1996, IV 1998, V 2001, VI 2003, VII 2005, VIII 2006, IX 2008 | M17: https://jfn.ac.lk/prof-s-pathmanathan/
A18: BK-0017 | B18: 2005 | D18: The Evolution of an Ethnic Identity: The Tamils of Sri Lanka c. 300 BCE to c. 1200 CE | E18: K. Indrapala | F18: MV Publications (Sydney); reissued Vijitha Yapa 2007, Ohm Books 2015 | G18: Book | H18: English | I18: Inscriptions / கல்வெட்டு; Brahmi / பிராமி | J18: Tamil Brahmi; inscriptions; ethnic history | K18: Yes | M18: https://en.wikipedia.org/wiki/K._Indrapala
A19: BK-0018 | B19: 2004 | D19: A Study of the Language of the Tamil Inscriptions of the 7th and 8th Centuries A.D. | E19: K. Kanapathypillai | F19: Kumaran Book House, Colombo-Chennai | G19: Book | H19: English | I19: Inscriptions / கல்வெட்டு | J19: Tamil inscriptions; epigraphy | K19: Yes | L19: 1st edition 2004 (reprint) | M19: https://unioncatalogue.dlp.gov.lk/Record/batt.35119/Similar
A20: BK-0019 | B20: 2004 | D20: Ilankaiyil Intu Camayam (Hinduism in Sri Lanka) | E20: S. Pathmanathan | F20: Kumaran Book House, Colombo-Chennai | G20: Book | H20: Tamil | J20: Hinduism; history | K20: Yes | M20: https://jfn.ac.lk/prof-s-pathmanathan/
A21: BK-0020 | B21: 2004 | D21: Tamil Literature and Historical Traditions in Sri Lanka | E21: S. Pathmanathan | F21: Kumaran Press | G21: Book | H21: Tamil | J21: history | K21: Yes | M21: https://en.wikipedia.org/wiki/S._Pathmanathan
A22: BK-0021 | B22: 2004 | D22: தமிழ் எழுத்தின் தோற்றம் (Origin of the Tamil Script) | E22: P. Pushparatnam | F22: District Secretariat, Jaffna | G22: Book | H22: Tamil | I22: Inscriptions / கல்வெட்டு; Brahmi / பிராமி | J22: பிராமி; script; epigraphy | K22: Yes | L22: Noolaham No. 4788; 126 pp. | M22: https://noolaham.org/wiki/index.php/தமிழ்_எழுத்தின்_தோற்றம்
A23: BK-0022 | B23: 2003 | D23: Early Tamil Epigraphy: From the Earliest Times to the Sixth Century A.D. | E23: Iravatham Mahadevan | F23: Cre-A, Chennai & Harvard University | G23: Book | H23: English | I23: Inscriptions / கல்வெட்டு; Brahmi / பிராமி | J23: Tamil Brahmi; epigraphy; Sri Lanka parallels | K23: Yes | L23: Discusses Sri Lankan Brahmi | M23: https://vedamsbooks.com/books/early_tamil_epigraphy_from_the_earliest_times_to_the_sixth_century_c_e_volume_1_tamil_brahmi_inscriptions
A24: BK-0023 | B24: 2003 | D24: Glimpses of Hindu Heritage | E24: S. Pathmanathan (joint ed.) | F24: Ministry of Hindu Religious Affairs | G24: Edited volume | H24: English | I24: Archaeology / தொல்லியல் | J24: heritage; bronzes | K24: Yes | M24: https://jfn.ac.lk/prof-s-pathmanathan/
A25: BK-0024 | B25: 2003 | C25: 2014-02-21 | D25: தொல்லியல் நோக்கில் இலங்கைத் தமிழர் பண்பாடு (Sri Lankan Tamil Culture from an Archaeological Perspective) | E25: P. Pushparatnam | F25: Bhavani Pathippagam | G25: Book | H25: Tamil | I25: Archaeology / தொல்லியல் | J25: தொல்லியல்; culture | K25: Yes | L25: Noolaham No. 4461; 240 pp. | M25: https://noolaham.org/wiki/index.php/தொல்லியல்_நோக்கில்_இலங்கைத்_தமிழர்_பண்பாடு
A26: BK-0025 | B26: 2002 | D26: Ancient Coins of Sri Lankan Tamil Rulers | E26: P. Pushparatnam | F26: Bavani Patippakam, Jaffna | G26: Book | H26: English | I26: Brahmi / பிராமி; Archaeology / தொல்லியல்; Coins / நாணயம் | J26: coins; Tamil Brahmi; archaeology | K26: Yes | L26: 192 pp. | M26: https://mannar.dlp.gov.lk/bib/9820
A27: BK-0026 | B27: 2002 | D27: Naka Dynasty as Gleaned from the Archaeological Evidences in Sri Lanka | E27: P. Pushparatnam | G27: Book | H27: English | I27: Inscriptions / கல்வெட்டு; Archaeology / தொல்லியல்; Coins / நாணயம் | J27: Naga; தொல்லியல்; coins; inscriptions | K27: Yes | L27: Noolaham No. 126188; 44 pp. | M27: https://noolaham.org/wiki/index.php/Naka_Dynasty_as_Gleaned_from_the_Archaeological_Evidences_in_Sri_Lanka
A28: BK-0027 | B28: 2002 | D28: தொல்லியல் நோக்கில் ஈழத்தமிழரின் பண்டையகால மதமும் கலையும் (Ancient Religion and Art of Eelam Tamils: An Archaeological Perspective) | E28: P. Pushparatnam | F28: Kumaran Book House | G28: Book | H28: Tamil | I28: Archaeology / தொல்லியல் | J28: தொல்லியல்; religion; art | K28: Yes | L28: Noolaham No. 4500; 177 pp. | M28: https://noolaham.org/wiki/index.php/தொல்லியல்_நோக்கில்_ஈழத்தமிழரின்_பண்டையகால_மதமும்_கலையும்
A29: BK-0028 | B29: 2001 | D29: Hindu Culture in Sri Lanka, Vol. 1: Temple Art & Architecture (ed.) | E29: S. Pathmanathan (ed.) | F29: Department of Hindu Religious & Cultural Affairs | G29: Book | H29: Tamil | I29: Archaeology / தொல்லியல் | J29: temple architecture; archaeology | K29: Yes | M29: https://en.wikipedia.org/wiki/S._Pathmanathan
A30: BK-0029 | B30: 2001 | D30: இலங்கைத் தமிழரின் பண்டைய கால நாணயங்கள் (Ancient Coins of Sri Lankan Tamils) | E30: P. Pushparatnam | F30: Bhavani Pathippagam | G30: Book | H30: Tamil | I30: Brahmi / பிராமி; Coins / நாணயம் | J30: நாணயம்; coins; Tamil Brahmi | K30: Yes | L30: Noolaham No. 4470; 219 pp. | M30: https://noolaham.org/wiki/index.php/இலங்கைத்_தமிழரின்_பண்டைய_கால_நாணயங்கள்
A31: BK-0030 | B31: 2001 | D31: பண்டைய இலங்கையில் தமிழும் தமிழரும் (Tamil and Tamils in Ancient Sri Lanka) | E31: P. Pushparatnam | F31: Colombo Tamil Sangam | G31: Book | H31: Tamil | I31: Inscriptions / கல்வெட்டு; Brahmi / பிராமி; Archaeology / தொல்லியல் | J31: பிராமி; கல்வெட்டு; தொல்லியல் | K31: Yes | L31: Noolaham No. 430; xiii+120 pp. | M31: https://noolaham.org/wiki/index.php/பண்டைய_இலங்கையில்_தமிழும்_தமிழரும்
A32: BK-0031 | B32: 2000 | D32: History and Archaeology of Sri Lanka, Vol. I: Reflections on a Heritage | E32: R.A.L.H. Gunawardana, S. Pathmanathan, M. Rohanadheera (eds.) | F32: Central Cultural Fund, Colombo | G32: Edited volume | H32: English | I32: Archaeology / தொல்லியல் | J32: archaeology; history | K32: Yes | M32: https://jfn.ac.lk/prof-s-pathmanathan/
A33: BK-0032 | B33: 2000 | D33: Temples of Siva in Sri Lanka | E33: S. Pathmanathan (chief ed.) | F33: Chinmaya Mission of Sri Lanka | G33: Edited volume | H33: English | I33: Inscriptions / கல்வெட்டு | J33: temples; inscriptions | K33: Yes | L33: Page gives 1999/2000 | M33: https://jfn.ac.lk/prof-s-pathmanathan/
A34: BK-0033 | B34: 1999 | D34: Ancient Sri Lankan coins / trade at Tissamaharama (Bopearachchi & Wickremesinhe) | E34: O. Bopearachchi, R. Wickremesinhe | F34: (Ruhuna: an ancient civilisation revisited) | G34: Book | H34: English | I34: Coins / நாணயம் | J34: coins; Tissamaharama; trade | K34: Yes | L34: Title to verify; reviewed Apr 2000 | M34: https://www.sundaytimes.lk/000423/plus3.html
A35: BK-0034 | B35: 1999 | D35: Studies in Sri Lankan Tamil Linguistics and Culture | E35: K. Balasubramaniyam, K. Ratnamalar, R. Subathini (eds.) | F35: Sri Lanka Offset Service, Chennai | G35: Book | H35: English | J35: culture; linguistics | K35: Yes | L35: 454 pp. | M35: https://unioncatalogue.dlp.gov.lk/Record/poin.4050/Description
A36: BK-0035 | B36: 1994 | D36: Epigraphia Zeylanica Vol. 3 (reprint) | E36: H. W. Codrington, S. Paranavitana | F36: Asian Educational Services | G36: Book | H36: English | I36: Inscriptions / கல்வெட்டு | J36: inscriptions; epigraphy | K36: No (earlier reference) | L36: Noolaham No. 4227; reprint (outside 30-year window, kept as reference) | M36: https://noolaham.org/wiki/index.php/Epigraphia_Zeylanica_3
A37: BK-0036 | B37: 1993 | D37: கோணேசர் கல்வெட்டு (Koneswara Inscription) | E37: I. Vadivel | F37: Department of Hindu Religious and Cultural Affairs | G37: Book | H37: Tamil | I37: Inscriptions / கல்வெட்டு | J37: கல்வெட்டு; Koneswaram; Trincomalee | K37: No (earlier reference) | L37: Noolaham No. 4824; 136 pp. | M37: https://noolaham.org/wiki/index.php/%E0%AE%95%E0%AF%8B%E0%AE%A3%E0%AF%87%E0%AE%9A%E0%AE%B0%E0%AF%8D_%E0%AE%95%E0%AE%B2%E0%AF%8D%E0%AE%B5%E0%AF%86%E0%AE%9F%E0%AF%8D%E0%AE%9F%E0%AF%81
A38: BK-0037 | B38: 1993 | D38: பூநகரி தொல்பொருளாய்வு (Poonakary Archaeological Survey) | E38: P. Pushparatnam | F38: University of Jaffna | G38: Book | H38: Tamil | I38: Brahmi / பிராமி; Archaeology / தொல்லியல் | J38: தொல்லியல்; Poonakari; Tamil Brahmi; potsherds | K38: No (earlier reference) | L38: Noolaham No. 67260; 238 pp. | M38: https://noolaham.org/wiki/index.php/%E0%AE%AA%E0%AF%82%E0%AE%A8%E0%AE%95%E0%AE%B0%E0%AE%BF_%E0%AE%A4%E0%AF%8A%E0%AE%B2%E0%AF%8D%E0%AE%AA%E0%AF%8A%E0%AE%B0%E0%AF%81%E0%AE%B3%E0%AE%BE%E0%AE%AF%E0%AF%8D%E0%AE%B5%E0%AF%81
A39: BK-0038 | B39: 1993 | D39: வட இலங்கையில் சிங்கைநகர் | E39: P. Pushparatnam | F39: Fr. G. A. Francis Joseph Manivila Committee | G39: Book | H39: Tamil | I39: Archaeology / தொல்லியல் | J39: Singai Nagar; archaeology | K39: No (earlier reference) | L39: Noolaham No. 38966; 56 pp. | M39: https://noolaham.org/wiki/index.php/வட_இலங்கையில்_சிங்கைநகர்
A40: BK-0039 | B40: 1992 | D40: தமிழர் வரலாறும் இலங்கை இடப்பெயர் ஆய்வும் | E40: Kathir Thanikasalam | F40: Saravana Pathippagam | G40: Book | H40: Tamil | J40: place names; history | K40: No (earlier reference) | L40: Noolaham No. 4510; 267 pp. | M40: https://noolaham.org/wiki/index.php/தமிழர்_வரலாறும்_இலங்கை_இடப்பெயர்_ஆய்வும்
...

Sheet Research Papers
A1: ID | B1: Year | C1: Date | D1: Title | E1: Author / Editor | F1: Publisher / Source | G1: Type | H1: Language | I1: Themes | J1: Keywords | K1: Within 1996-2026 | L1: Notes | M1: URL
A2: RP-0001 | B2: 2026 | D2: Hindu Idols Revealing the Cultural Connections between Northern Sri Lanka and South India | E2: S. Aniththa, Ushanthy Arunpirasanth | F2: First International Conference in Saiva Siddhanta, University of Jaffna | G2: Conference paper | H2: English | I2: Archaeology / தொல்லியல் | J2: sculpture; archaeology | K2: Yes | M2: https://www.his.jfn.ac.lk/index.php/__trashed/
A3: RP-0002 | B3: 2026 | C3: 2026-01-01 | D3: Human Skeleton of Kithulgala Beli-lena rockshelter in Sri Lanka | E3: Pahiyangala Sumangala, Nimal Perera | F3: Social Science and Humanities Journal | G3: Article | H3: English | K3: Yes | L3: OpenAlex query: rock art Sri Lanka. Auto-collected 2026-10-14 (openalex); review. | M3: https://doi.org/10.18535/sshj.v10i08.2489
A4: RP-0003 | B4: 2026 | C4: 2026-01-01 | D4: Tamil Words in Early Prakrit Inscriptions in Sri Lanka | E4: Karan Damodaram Pillai | F4: SSRN Electronic Journal | G4: Preprint | H4: English | I4: Inscriptions / கல்வெட்டு | J4: inscription; inscriptions | K4: Yes | L4: OpenAlex query: Tamil inscription Sri Lanka. Auto-collected 2026-10-14 (openalex); review. | M4: https://doi.org/10.2139/ssrn.6422478
A5: RP-0004 | B5: 2026 | C5: 2026-02-01 | D5: Reinterpreting encounters: comparative study of William of Rubruck's travelogue and Sri Lankan inscriptions in medieval road contexts | E5: Madhavi Madhushani Kahapala Arachchi | G5: Dissertation | H5: English | I5: Inscriptions / கல்வெட்டு | J5: inscription; inscriptions | K5: Yes | L5: OpenAlex query: Tamil inscription Sri Lanka. Auto-collected 2026-10-14 (openalex); review. | M5: https://doi.org/10.48336/247
A6: RP-0005 | B6: 2026 | C6: 2026-04-01 | D6: Coastal foragers beyond the mainland: Seafaring and early island settlement on Velanai, Jaffna, Sri Lanka, ca. 3460 cal BP | E6: Thilanka M. Siriwardana, Indika Ruwan Jayasekara, Janeena Nonis, Nadeera H. Dissanayake, Jude Perera | F6: The Journal of Island and Coastal Archaeology | G6: Article | H6: English | I6: Archaeology / தொல்லியல் | K6: Yes | L6: OpenAlex query: Jaffna archaeology. Auto-collected 2026-10-14 (openalex); review. | M6: https://doi.org/10.1080/15564894.2026.2624853
A7: RP-0006 | B7: 2026 | C7: 2026-04-04 | D7: Late quaternary shell deposits in Northwestern Sri Lanka: New data on chronology, stratigraphy, and contents | E7: Thilanka M. Siriwardana, Indika Ruwan Jayasekara, Nadeera H. Dissanayake | F7: Quaternary International | G7: Article | H7: English | K7: Yes | L7: OpenAlex query: Jaffna archaeology. Auto-collected 2026-10-14 (openalex); review. | M7: https://doi.org/10.1016/j.quaint.2026.110251
A8: RP-0007 | B8: 2026 | C8: 2026-04-14 | D8: Myanmar’s Prehistoric Rock Art: a Comparative Study with Assam and Sri Lanka | E8: Win Pa Pa Lwin, Pyiet Phyo Kyaw | F8: The South East Asian Review | G8: Journal article | H8: English | I8: Rock art / பாறை ஓவியம் | J8: rock art | K8: Yes | L8: Crossref query: rock art Sri Lanka. Auto-collected 2026-10-14 (crossref); review. | M8: https://doi.org/10.32381/sear.2025.50.9
A9: RP-0008 | B9: 2026 | C9: 2026-07-01 | D9: Communicative Practices and Societal Structures: Insights from Early Brahmi Inscriptions in Sri Lanka (3rd Century BCE–1st Century CE) | E9: J. D. A. Kumara | F9: KDU Journal of Multidisciplinary Studies | G9: Article | H9: English | I9: Inscriptions / கல்வெட்டு; Brahmi / பிராமி | J9: inscription; inscriptions; brahmi | K9: Yes | L9: OpenAlex query: Tamil inscription Sri Lanka. Auto-collected 2026-10-14 (openalex); review. | M9: https://doi.org/10.4038/kjms.v8i1.183
A10: RP-0009 | B10: 2026 | C10: 2026-07-06 | D10: Ornaments of Microlithic Period in Sri Lanka: Based on Cultural Deposit in Rock Shelters | E10: Pahiyangala Sumangala | F10: Pravacana | G10: Article | H10: English | K10: Yes | L10: OpenAlex query: rock art Sri Lanka. Auto-collected 2026-10-14 (openalex); review. | M10: https://doi.org/10.4038/p.v16i1.58
A11: RP-0010 | B11: 2026 | C11: 2026-07-07 | D11: Localizing Heritage: Archaeologies of the Recent Past in Postwar Jaffna, Sri Lanka | E11: Gill Juleff, Thamotharampillai Sanathanan, Ruth Young, John P. Cooper, Emma Dwyer, Adrián Oyaneder | F11: Historical Archaeology | G11: Journal article | H11: English | I11: Archaeology / தொல்லியல் | K11: Yes | L11: Crossref query: Jaffna archaeology. Auto-collected 2026-10-14 (crossref); review. | M11: https://doi.org/10.1007/s41636-026-00636-0
A12: RP-0011 | B12: 2026 | C12: 2026-09-21 | D12: A Historical Study of the Tamil Inscriptions Discovered at the Buddhist Heritage Site of Velgam Vehera | E12: U.S.Y. Sahan Mahesh Senarath yapa | F12: Zenodo (CERN European Organization for Nuclear Research) | G12: Conference paper | H12: English | I12: Inscriptions / கல்வெட்டு; Archaeology / தொல்லியல் | J12: inscription; inscriptions | K12: Yes | L12: OpenAlex query: Tamil inscription Sri Lanka. Auto-collected 2026-10-14 (openalex); review. | M12: https://doi.org/10.5281/zenodo.22870959
A13: RP-0012 | B13: 2025 | D13: Investigation of Ancient Pre-colonial Monuments in Jaffna, Sri Lanka | F13: NIIBS Faculty of Humanities & Social Sciences | G13: Journal article | H13: English | I13: Archaeology / தொல்லியல் | J13: monuments; Jaffna | K13: Yes | L13: Upload Feb 2025 | M13: https://fhss.niibs.lk/wp-content/uploads/2025/02/Investigation-of-Ancient-Pre-colonial-Monuments-in-Jaffna-Sri-Lanka.pdf
A14: RP-0013 | B14: 2025 | D14: The Chola Rule that Shed Light on the History of Sri Lankan Tamils: A Historical Perspective | E14: S. Aniththa | F14: International Archaeological Conference 2025, International Tamizhkkalvi Research Institute, Tamil Nadu | G14: Conference paper | H14: Tamil | I14: Inscriptions / கல்வெட்டு | J14: Chola; inscriptions | K14: Yes | M14: https://www.his.jfn.ac.lk/index.php/__trashed/
A15: RP-0014 | B15: 2025 | C15: 2025-03-08 | D15: Palimpsests: Material Religion and Political Archaeology at Kurunthaloor Vihara, Sri Lanka | E15: A. Suganthan | F15: AAR Southeast Regional Conference (AARSE 2025), Florida | G15: Conference paper | H15: English | I15: Archaeology / தொல்லியல் | J15: Kurunthurmalai; political archaeology | K15: Yes | M15: https://www.his.jfn.ac.lk/index.php/mrs-ajiththa-suganthan/
A16: RP-0015 | B16: 2025 | C16: 2025-05-15 | D16: පලනනර අවධය මරට අභයනතර වළඳ නගරවල කරයකරතවය සහ වදශ වළඳ ශරණවල භමකව [The Operation of the Country's Internal Trading Hubs and the Role of Foreign Trade Guilds During the Polonnaruwa Period] | E16: M. K. L. Irangani | F16: Pravacana | G16: Article | H16: English | K16: Yes | L16: OpenAlex query: Jaffna archaeology. Auto-collected 2026-10-14 (openalex); review. | M16: https://doi.org/10.4038/p.v15i2.21
A17: RP-0016 | B17: 2025 | C17: 2025-06-30 | D17: THE SIGIRIYA MURALS OF SRI LANKA: A COMPREHENSIVE ART HISTORICAL ANALYSIS | E17: Independent Researcher, KHUSHALI JAIN | F17: VESTIGIA INDICA BSSS Journal of History & Archaeology | G17: Article | H17: English | K17: Yes | L17: OpenAlex query: rock art Sri Lanka. Auto-collected 2026-10-14 (openalex); review. | M17: https://doi.org/10.51767/jha0308
A18: RP-0017 | B18: 2025 | C18: 2025-10-17 | D18: Interactions between Northern Sri Lanka and South India: A Study Based on the Yalppana Vaipavamalai | E18: G. Jeyatheeswaran, R. Udaiachandran | F18: HuSS International Journal of Research in Humanities and Social Sciences | G18: Article | H18: English | K18: Yes | L18: OpenAlex query: Tamil inscription Sri Lanka. Auto-collected 2026-10-14 (openalex); review. | M18: https://doi.org/10.15613/hijrh/2025/v12i1/52698
A19: RP-0018 | B19: 2025 | C19: 2025-10-31 | D19: A STUDY OF NON-BRAHMI SYMBOLS CREATED FROM THE EARLY BRAHMI SCRIPT | E19: N. Bandara | F19: Third Desk Research Conference | G19: Proceedings article | H19: English | I19: Brahmi / பிராமி | J19: brahmi | K19: Yes | L19: Crossref query: Tissamaharama Brahmi. Auto-collected 2026-10-14 (crossref); review. | M19: https://doi.org/10.64920/drc2025027
A20: RP-0019 | B20: 2025 | C20: 2025-12-01 | D20: Merchant Guilds as Agents of Trade, Military, and Religious Integration: Valangiyar and Manigramam Networks Across South India, Sri Lanka, and Southeast Asia | E20: Nayomi Dinuka Kekulawala, Dananjaya Gamalath | F20: Nāgānanda International Journal of Humanities & Social Sciences, Vol. 10, No. 05, pp. 40-51 | G20: Journal article | H20: English | I20: Inscriptions / கல்வெட்டு | J20: merchant guilds; Valanjiyar; Manigramam; inscriptions | K20: Yes | M20: https://nijhss.niibs.lk/download/?id=52
A21: RP-0020 | B21: 2025 | C21: 2025-12-20 | D21: SRI LANKAN MARITIME LAW GOES BACK TO THE SECOND CENTURY BC | E21: Faiz Marikar | F21: Crisia | G21: Article | H21: English | K21: Yes | L21: OpenAlex query: Tamil inscription Sri Lanka. Auto-collected 2026-10-14 (openalex); review. | M21: https://doi.org/10.66142/crisia.2025.06
A22: RP-0021 | B22: 2025 | C22: 2025-12-29 | D22: Collective and Proactive Female Patronage in Sri Lankan Buddhist Temple Art | E22: Dulma Karunarathna | F22: Ancient Lanka | G22: Article | H22: English | K22: Yes | L22: OpenAlex query: Tamil inscription Sri Lanka. Auto-collected 2026-10-14 (openalex); review. | M22: https://doi.org/10.29173/anlk856
A23: RP-0022 | B23: 2025 | C23: 2025-12-29 | D23: Stone, Symbol, and Leisure: A Reassessment of Geometric Symbols on the Stone-Paved Terrace of Jetavana Stupa, Sri Lanka | E23: K.W. Chithramala Tharangani | F23: Ancient Lanka | G23: Journal article | H23: English | K23: Yes | L23: Crossref query: hero stone Sri Lanka. Auto-collected 2026-10-14 (crossref); review. | M23: https://doi.org/10.29173/anlk872
A24: RP-0023 | B24: 2025 | C24: 2025-12-30 | D24: Reconstructing Past Settlements through Soil Characterization: Vessagiriya, Sri Lanka | E24: Chammi P. Attanayake, Ranjith B. Mapa, Sudharshan Seneviratne, Dulma Karunarathna | F24: Ancient Lanka | G24: Article | H24: English | I24: Archaeology / தொல்லியல் | K24: Yes | L24: OpenAlex query: Tamil inscription Sri Lanka. Auto-collected 2026-10-14 (openalex); review. | M24: https://doi.org/10.29173/anlk858
A25: RP-0024 | B25: 2025 | C25: 2025-12-31 | D25: இலஙகயன பழஙகட இனததவரகளன வடவர சமகததன மழயம, பணபடடமசஙகளம. The language and cultural aspects of the Veddah community, the indigenous people of Sri Lanka | E25: T. Yujanthan | F25: Journal of Tamil Peraivu | G25: Article | H25: English | K25: Yes | L25: OpenAlex query: Tamil inscription Sri Lanka. Auto-collected 2026-10-14 (openalex); review. | M25: https://doi.org/10.22452/jtp.vol14no2.12
A26: RP-0025 | B26: 2024 | D26: Serpent Deities (Nagas) in Ancient Sri Lanka: Evidence from the Kaddukarai Excavation | E26: A. Suganthan | F26: More-than-human Religion conference, Florida State University | G26: Conference paper | H26: English | I26: Archaeology / தொல்லியல் | J26: Naga; Kattukarai excavation | K26: Yes | M26: https://www.his.jfn.ac.lk/index.php/mrs-ajiththa-suganthan/
A27: RP-0026 | B27: 2024 | D27: The Role of Tamil Language in Sinhala Kingdoms during the Early and Medieval Period of Sri Lanka | E27: S. Aniththa | F27: 12th International Symposium, South Eastern University of Sri Lanka | G27: Conference paper | H27: English | I27: Inscriptions / கல்வெட்டு | J27: Tamil inscriptions; language | K27: Yes | M27: https://www.his.jfn.ac.lk/index.php/__trashed/
A28: RP-0027 | B28: 2024 | C28: 2024-02-23 | D28: Heritage and decoloniality: Reflections from Sri Lanka—A conversation | E28: Hasini Haputhanthri, Gill Juleff, Thamotharampillai Sanathanan | F28: American Anthropologist | G28: Article | H28: English | I28: Archaeology / தொல்லியல் | K28: Yes | L28: OpenAlex query: Jaffna archaeology. Auto-collected 2026-10-14 (openalex); review. | M28: https://doi.org/10.1111/aman.13949
A29: RP-0028 | B29: 2024 | C29: 2024-05-15 | D29: Cheng Ho's Visits to Sri Lanka and the discovery of Oldest Arwi Script Found in Galle Trilingual Inscription | E29: Faiz M. M. T. Marikar, Manjula Karunathilaka | F29: International Journal of Modern Anthropology | G29: Article | H29: English | I29: Inscriptions / கல்வெட்டு | J29: inscription | K29: Yes | L29: OpenAlex query: Tamil inscription Sri Lanka. Auto-collected 2026-10-14 (openalex); review. | M29: https://doi.org/10.4314/ijma.v3i21.3
A30: RP-0029 | B30: 2024 | C30: 2024-12-29 | D30: From Early Migrations to Colonial Encounters: Archaeological Research on the Mannar-Jaffna Seaboard, Sri Lanka | E30: Thilanka M. Siriwardana | F30: Ancient Lanka | G30: Article | H30: English | I30: Archaeology / தொல்லியல் | J30: archaeological | K30: Yes | L30: OpenAlex query: Jaffna archaeology. Auto-collected 2026-10-14 (openalex); review. | M30: https://doi.org/10.29173/anlk817
A31: RP-0030 | B31: 2024 | C31: 2024-12-29 | D31: Historical Demaḷa Mahā Sǣya of Polonnaruwa, Sri Lanka: An Archaeological Analysis of its Construction Technology | E31: Priyantha Marasinghe, Nimal Perera | F31: Ancient Lanka | G31: Journal article | H31: English | I31: Archaeology / தொல்லியல் | J31: archaeological | K31: Yes | L31: Crossref query: Polonnaruwa Tamil inscription. Auto-collected 2026-10-14 (crossref); review. | M31: https://doi.org/10.29173/anlk838
A32: RP-0031 | B32: 2023 | D32: 'Thana' given by Sri Lankan women as reflected through literature and inscription sources | E32: S. Aniththa | F32: National Conference on Historical Studies, University of Kelaniya | G32: Conference paper | H32: English | I32: Inscriptions / கல்வெட்டு | J32: inscriptions; donations | K32: Yes | M32: https://www.his.jfn.ac.lk/index.php/__trashed/
A33: RP-0032 | B33: 2023 | D33: Influence of Hinduism during the Gampola Kingdom - A Study Based on the Inscriptions | E33: Ushanthy Arunpirasanth | F33: 2nd National Research Symposium on Social Sciences and Humanities, Rajarata University | G33: Conference paper | H33: English | I33: Inscriptions / கல்வெட்டு | J33: inscriptions; Gampola | K33: Yes | M33: https://www.his.jfn.ac.lk/index.php/ms-mahalingam-ushanthy/
A34: RP-0033 | B34: 2023 | D34: Integrative Approaches in Archaeology: The Imperative for Multidisciplinary Research | E34: A. Suganthan, P. Pushparatnam | F34: Nāgānanda International Journal of Humanities and Social Science, 1(1), pp. 1-13 | G34: Journal article | H34: English | I34: Archaeology / தொல்லியல் | J34: archaeology; methodology | K34: Yes | M34: https://www.his.jfn.ac.lk/index.php/mrs-ajiththa-suganthan/
A35: RP-0034 | B35: 2023 | D35: Ipankadduwa Megalithic Centre and Museum | E35: Thulasika Dineshan | F35: INTSYM 2023, South Eastern University of Sri Lanka | G35: Conference paper | H35: English | I35: Archaeology / தொல்லியல் | J35: megalithic; Ibbankatuwa | K35: Yes | M35: https://www.his.jfn.ac.lk/?p=1706
A36: RP-0035 | B36: 2023 | D36: Some considerations on Dutch colonial architecture: The Kruys church at Jaffna Fort | E36: A. Suganthan | F36: Archaeology: South Asian Journal of Archaeology, University of Kelaniya | G36: Journal article | H36: English | I36: Archaeology / தொல்லியல் | J36: archaeology; Jaffna Fort | K36: Yes | M36: https://www.his.jfn.ac.lk/index.php/mrs-ajiththa-suganthan/
A37: RP-0036 | B37: 2023 | D37: Tevaratiyars (Women of Temples) in Sri Lanka: A Study Based on Epigraphy | E37: S. Aniththa | F37: 1st International Conference on Gender Studies, University of Sri Jayewardenepura | G37: Conference paper | H37: English | I37: Inscriptions / கல்வெட்டு | J37: epigraphy; கல்வெட்டு | K37: Yes | M37: https://www.his.jfn.ac.lk/index.php/__trashed/
A38: RP-0037 | B38: 2023 | D38: The Role of Brahmins in the Sinhalese Monarchy: A Study Based on the Kingdom of Anuradhapura | E38: S. Aniththa | F38: 2nd National Research Symposium, Rajarata University of Sri Lanka | G38: Conference paper | H38: English | I38: Inscriptions / கல்வெட்டு; Brahmi / பிராமி | J38: Brahmins; inscriptions | K38: Yes | M38: https://www.his.jfn.ac.lk/index.php/__trashed/
A39: RP-0038 | B39: 2023 | D39: The Role of Tamil Officers in Sinhalese Monarchy up to 13th Century A.D.: A Review | E39: S. Aniththa | F39: 11th International Symposium, South Eastern University of Sri Lanka | G39: Conference paper | H39: English | I39: Inscriptions / கல்வெட்டு | J39: inscriptions; officials | K39: Yes | M39: https://www.his.jfn.ac.lk/index.php/__trashed/
A40: RP-0039 | B40: 2023 | C40: 2023-04-01 | D40: Kalinga in Sri Lankan Historiography | E40: Chrisdina Nirojini Mosasrupan | F40: Shanlax International Journal of Tamil Research | G40: Journal article | H40: Tamil | I40: Inscriptions / கல்வெட்டு | J40: Kalinga Magha; inscriptions | K40: Yes | L40: Year to verify | M40: https://shanlaxjournals.in/journals/index.php/tamil/article/view/6193
...

Sheet Newspaper Articles
A1: ID | B1: Year | C1: Date | D1: Title | E1: Author / Editor | F1: Publisher / Source | G1: Type | H1: Language | I1: Themes | J1: Keywords | K1: Within 1996-2026 | L1: Notes | M1: URL
A2: NW-0001 | B2: 2026 | D2: Glimpses of an Ancient Civilisation: Society and Culture in Jaffna | F2: The Island | G2: Book review | H2: English | I2: Brahmi / பிராமி | J2: Pathmanathan; book; Tamil-Brahmi | K2: Yes | M2: https://island.lk/glimpses-of-an-ancient-civilisation-society-and-culture-in-jaffna/
A3: NW-0002 | B3: 2026 | C3: 2026-01-13 | D3: A Historian In Focus: The Dark Side Of S Pathmanathan | E3: Darshanie Ratnawalli | F3: Colombo Telegraph | G3: Opinion | H3: English | I3: Brahmi / பிராமி | J3: Brahmi; Pathmanathan; debate | K3: Yes | M3: https://www.colombotelegraph.com/index.php/a-historian-in-focus-the-dark-side-of-s-pathmanathan/
A4: NW-0003 | B4: 2026 | C4: 2026-01-23 | D4: செங்கலடியில் அனுமதியின்றி நாட்டப்பட்ட தொல்பொருள் அடையாளப் பலகைகளை அகற்ற நடவடிக்கை | F4: Tamilwin | G4: News | H4: Tamil | I4: Archaeology / தொல்லியல் | J4: தொல்லியல்; Chenkalady; signboards | K4: Yes | L4: Heritage dispute; date from URL timestamp | M4: https://tamilwin.com/article/remove-archaeological-permission-in-chengaladi-1769150736
A5: NW-0004 | B5: 2026 | C5: 2026-04-18 | D5: New book by Tamil historian re-examines early Jaffna civilisation through inscriptions and archaeology | F5: Tamil Guardian | G5: News | H5: English | I5: Inscriptions / கல்வெட்டு; Archaeology / தொல்லியல் | J5: Pathmanathan; book launch; inscriptions | K5: Yes | M5: https://www.tamilguardian.com/content/prof-pathmanathans-new-book-sheds-light-early-jaffna-civilisation
A6: NW-0005 | B6: 2026 | C6: 2026-10-07 | D6: Archaeology Department seeks 260 acres as monk targets second Hindu temple in Vavuniya | F6: Tamil Guardian | G6: News | H6: English | I6: Archaeology / தொல்லியல் | J6: archaeology | K6: Yes | L6: Google News query: archaeology Vanni Tamil. Auto-collected 2026-10-14 (news); review. | M6: https://news.google.com/rss/articles/CBMiyAFBVV95cUxPck1TdFVQcDc3dXR2RzBfNko0V09ZWG44aUZsTWE3WmJIWWRkd3NXRDloS3FNbk9CbjFqNV9oTVo5MzA4MU1kYmU4b0VyZVRsMlNzOWJSSklRcnRySHNzaGRVWXl2VUhEVF9YV3JjVmNndC15STkwUmotOEhSTmNFQ1JZWUtTQktXNThKSzA3d25oWmpXVkxhVUZfaUpaOGpiaEx6enF2dmtmNGZpUXNRR3dEWTVETUdsb3BXY0FlWXFrVWNSMFdjNQ?oc=5
A7: NW-0006 | B7: 2025 | C7: 2025-04-19 | D7: UNESCO recognizes Sri Lanka's Trilingual Inscription and 'Panadurawaadaya' documents as World Heritage | F7: Daily News (Sri Lanka) | G7: News | H7: English | I7: Inscriptions / கல்வெட்டு; Archaeology / தொல்லியல் | J7: Galle trilingual inscription; UNESCO | K7: Yes | M7: https://www.dailynews.lk/2025/04/19/admin-catagories/breaking-news/763455/unesco-recognizes-sri-lankas-trilingual-inscription-and-panadurawaadaya-documents-as-world-heritage/
A8: NW-0007 | B8: 2025 | C8: 2025-04-22 | D8: Significance of Galle Trilingual Inscription's inclusion in the World Heritage List | F8: Daily News (Sri Lanka) | G8: Feature | H8: English | I8: Inscriptions / கல்வெட்டு; Archaeology / தொல்லியல் | J8: Galle trilingual inscription; Tamil; UNESCO | K8: Yes | M8: https://dailynews.lk/2025/04/22/features/764498/significance-of-galle-trilingual-inscriptions-inclusion-in-the-world-heritage-list/
A9: NW-0008 | B9: 2025 | C9: 2025-11-01 | D9: Sinhala Buddhist monk alleges archaeology department official planted 'artefacts' in Kurunthurmalai | F9: Tamil Guardian | G9: News | H9: English | I9: Archaeology / தொல்லியல் | J9: archaeology | K9: Yes | L9: Google News query: archaeology Vanni Tamil. Auto-collected 2026-10-14 (news); review. | M9: https://news.google.com/rss/articles/CBMiqAFBVV95cUxQWTZoOUtnRWRBOE11dkVZMDdERkVIdUt0Z08tbk04b0h6LWFEUHdDQ1ZtdU1QSE83R0pVN0FPZTB6cWVpNC1ISGtGTUkzLWhDRFhtamJXeFo4ZjJpM2RUQWZGb3dTR0RHVzhmZ2ZQQ0RRVjhGMl9LclZOVFhlZlBTQUs3RElIQ3BSYzJlc0lLVGxfYmxhSnZIWldBdTRlMHlqekp0MzNsRGs?oc=5
A10: NW-0009 | B10: 2025 | C10: 2025-11-21 | D10: மட்டக்களப்பில் துரத்தியடிக்கப்பட்ட தொல்லியல் திணைக்களத்தினர் | F10: IBC Tamil | G10: News | H10: Tamil | I10: Archaeology / தொல்லியல் | J10: தொல்லியல்; Batticaloa | K10: Yes | L10: Heritage dispute; date from URL timestamp | M10: https://ibctamil.com/article/department-of-archaeology-personnel-chased-away-1763743917
A11: NW-0010 | B11: 2025 | C11: 2025-12-27 | D11: வவுனியா கல்லுமலை பிள்ளையார் ஆலய வளாகத்தில் முளைக்கும் விகாரை! | F11: IBC Tamil | G11: News | H11: Tamil | I11: Archaeology / தொல்லியல் | J11: தொல்லியல்; archaeology department; Vavuniya | K11: Yes | L11: Heritage dispute; date from URL timestamp | M11: https://ibctamil.com/article/archaeology-dep-to-construct-a-vihara-in-vavuniya-1766829487
A12: NW-0011 | B12: 2025 | C12: 2025-12-27 | D12: வவுனியா பிள்ளையார் ஆலய வளாகத்தில் விகாரை அமைக்கும் தொல்பொருள் திணைக்களம் | F12: Tamilwin | G12: News | H12: Tamil | I12: Archaeology / தொல்லியல் | J12: தொல்லியல்; archaeology department; Vavuniya | K12: Yes | L12: Heritage dispute; date from URL timestamp | M12: https://tamilwin.com/article/viharaya-in-the-pillayar-temple-complex-vavuniya-1766838422
A13: NW-0012 | B13: 2024 | C13: 2024-02-24 | D13: இலங்கையில் கண்டுபிடிக்கப்பட்ட நிலக்கீழ் நகரம் | F13: IBC Tamil | G13: News | H13: Tamil | I13: Archaeology / தொல்லியல் | J13: தொல்லியல்; Polonnaruwa | K13: Yes | L13: URL timestamp Feb 2024 | M13: https://ibctamil.com/article/an-underground-city-discovered-in-polonnaruwa-sl-1708747886
A14: NW-0013 | B14: 2024 | C14: 2024-07-06 | D14: Exploring Sri Lanka's archaeological and cultural treasures | F14: Wanderlust Travel Magazine | G14: News | H14: English | I14: Archaeology / தொல்லியல் | J14: archaeological | K14: Yes | L14: Google News query: rock art Sri Lanka. Auto-collected 2026-10-14 (news); review. | M14: https://news.google.com/rss/articles/CBMiggFBVV95cUxQczl0U3RlM2Y4UjFBSU1ULWtUTEpFaXZIb3pBLTRkTmpoOEh5Nzc4MzlMNVM4MGpEd0FhWFVJTE84ZnZ3ZnVDUWVjUnBOVThrTndsX3gxT0g0ZkxlWDQyLWVRNDdFZ25HXzdlZWZmQ2ZZZFlMUHVHYm1DLWdVZjVuNmdR?oc=5
A15: NW-0014 | B15: 2024 | C15: 2024-08-22 | D15: Fact Check: அனுமனின் கதாயுதம் ஒன்று இலங்கையில் தொல்லியல் அகழாய்வின் போது கண்டெடுக்கப்பட்டதா? | F15: NewsMeter | G15: News | H15: Tamil | I15: Archaeology / தொல்லியல் | J15: தொல்லியல் | K15: Yes | L15: Google News query: தொல்லியல் இலங்கை தமிழ். Auto-collected 2026-10-14 (news); review. | M15: https://news.google.com/rss/articles/CBMinAFBVV95cUxPc0xxall2V0toUHFjdEpHdGd3YV9VWTZja0htbkJXNFEyNmVJMlF1WGJsZnlXeXVlemltbDRfMHdYYXlLZ0swRlVVbW1uU0pUc3ppZkc2Qmlnc0Y1WFl3SXpINzJFRUZYVWxNRDV5YUNEanAxZE4tMG9hT0hZQnNXYWNhM1VMRHV6b25iN3ZPZUNzZzJYeVB5VlZlUEY?oc=5
A16: NW-0015 | B16: 2023 | C16: 2023-03-27 | D16: வவுனியா - வெடுக்குநாறி மலை விவகாரம்: வன்மையாகக் கண்டிப்பதாகக் கூறும் அனந்தி! | F16: Tamilwin | G16: News | H16: Tamil | I16: Archaeology / தொல்லியல் | J16: Vedukkunari hill; archaeology; heritage | K16: Yes | L16: Heritage dispute; date from URL timestamp | M16: https://tamilwin.com/article/vedukunari-hill-affair-1679899848
A17: NW-0016 | B17: 2023 | C17: 2023-03-29 | D17: இலங்கையின் தொல்லியல் சிறப்புமிக்க ஆதிலிங்கேஸ்வரர் ஆலயம் உடைப்பு - அரசாங்கம் என்ன சொல்கிறது? | F17: BBC | G17: News | H17: Tamil | I17: Archaeology / தொல்லியல் | J17: தொல்லியல் | K17: Yes | L17: Google News query: தொல்லியல் இலங்கை தமிழ். Auto-collected 2026-10-14 (news); review. | M17: https://news.google.com/rss/articles/CBMiW0FVX3lxTE02dFpiVWFGNWlFWExhWUxUelI2X0tYY3kxak4tYWx2ZDhrSld0SC11ZzVxZXhLV3lNWEhMeUdaQUZfZWQ2MkNLMk9JMTNUUkVwRzhlUDFvZ3VlWlHSAWBBVV95cUxPOUhPNUd4LXgwN2hvRVJod0pXWnNDbjJ1S1U3U0xRVHpDQzZCYldGY3hBZWtCbGFycEt3N1U4bzNPT0dEeXVkRnc3QVdRLXNuU0l3ZXp3YlZ1dWJZSVRRQ04?oc=5
A18: NW-0017 | B18: 2023 | C18: 2023-08-11 | D18: கீரிமலை கேணியையும் தொல்லியல் திணைக்களம் கட்டுப்பாட்டுக்குள் கொண்டுவர முயற்சி - அகில இலங்கை இந்து மாமன்றம் | F18: Lanka Truth | G18: News | H18: Tamil | I18: Archaeology / தொல்லியல் | J18: தொல்லியல் | K18: Yes | L18: Google News query: தொல்லியல் இலங்கை தமிழ். Auto-collected 2026-10-14 (news); review. | M18: https://news.google.com/rss/articles/CBMiSkFVX3lxTE9RWHRpZjlDZE92MEg4bC1VRXFNMjNpSlotREpZclVwU2tncGcyRWFNUnpxQ1ZJTmlRZS1VanBPWl9XNVdjcWhtd29R?oc=5
A19: NW-0018 | B19: 2023 | C19: 2023-09-13 | D19: இலங்கை இனவாத குழுக்கள் சர்ச்சைக்குரிய தொல்பொருள் பிரதேசம் தொடர்பாக இனவாத பதட்டங்களை கிளப்பி வருகின்றன | F19: World Socialist Web Site | G19: News | H19: Tamil | I19: Archaeology / தொல்லியல் | J19: தொல்பொருள் | K19: Yes | L19: Google News query: தொல்லியல் இலங்கை தமிழ். Auto-collected 2026-10-14 (news); review. | M19: https://news.google.com/rss/articles/CBMiaEFVX3lxTE9mazdldjk2bWROTF9UYjJKOWhvMk9hQUwwcGdfbjgwYVN4a2phYktJU3RfWHpUSzFxZlpLQmhURWxacjJWYTNFZEFMNlFuWG13S1Rra1ZVZGdPcU40bmZxS2p5M09wT09h?oc=5
A20: NW-0019 | B20: 2023 | C20: 2023-09-27 | D20: Shared heritage of archaeological sites in the North and East | F20: Daily Mirror - Sri Lanka | G20: News | H20: English | I20: Archaeology / தொல்லியல் | J20: archaeological | K20: Yes | L20: Google News query: Tamil inscription Sri Lanka. Auto-collected 2026-10-14 (news); review. | M20: https://news.google.com/rss/articles/CBMiqwFBVV95cUxPWG1naE01WFRxUkhWX2kwWWRWTlJaZy1heUNCOG9pcTZ5eUtqbjlPc1BRVHlBQm1ST0hvQmk5TDlMeVZXQlNwUXBWelhMdGNmLVc3ck0yR2MzWUtSS0xQdW5uRjhFa0lPTVZ2Q08yUkg3aXhLeGdtdllzYWZGV2pad2IzbkIwdk54T0tneHl3bzZUU0gyRWRIU2gwX21BUmV1Zm1Vc2pZNkx3cms?oc=5
... A24: NW-0023 | B24: 2021 | C24: 2021-11-22 | D24: இலங்கை தமிழர் வரலாறு: புதிய தகவல்களைக் கூறும் 13ஆம் நூற்றாண்டு கல்வெட்டு | F24: BBC | G24: News | H24: Tamil | I24: Inscriptions / கல்வெட்டு | J24: கல்வெட்டு | K24: Yes | L24: Google News query: கல்வெட்டு இலங்கை. Auto-collected 2026-10-14 (news); review. | M24: https://news.google.com/rss/articles/CBMiV0FVX3lxTE9uajJZaVFzTk1NVFFqRDNVVTNHU3dVc0xySDB6Tk9LbmxIeHR4SkozOUxJN2lQTlFMa2hjaXJXakVjaWJmZ0xJcW1EQ0k3bUUyLVpfbVpMUdIBXEFVX3lxTFAtSEZTSzdPd25Oa1FFMFB2NGNHRFVIYjB4NWdIbXl3a0pmNXlRcjItZjhmLWNxbHItLUFUamVkSWpxblA3YUU5SUoxclFVTDhNR1pXaVZTelFLc2N1?oc=5
A25: NW-0024 | B25: 2021 | C25: 2023-01-03 | D25: தமிழ் இராச்சியத்தின் தோற்றம் பற்றிய முன்னைய வரலாற்றுப் பார்வையை மீள் வாசிப்பிற்கு உட்படுத்தும் அரிய தமிழ்க் கல்வெட்டு திருகோணமலையில் கண்டுபிடிப்பு! | E25: பரமு புஷ்பரட்ணம் | F25: Athavan News | G25: News | H25: Tamil | I25: Inscriptions / கல்வெட்டு | J25: கல்வெட்டு; Trincomalee; Tamil kingdom | K25: Yes | M25: https://athavannews.com/2021/1251617
A26: NW-0025 | B26: 2020 | C26: 2020-12-01 | D26: Sri Lanka’s archaeology department acquires ‘ancient monastery site’ in Jaffna | F26: Tamil Guardian | G26: News | H26: English | I26: Archaeology / தொல்லியல் | J26: archaeology | K26: Yes | L26: Google News query: archaeology Jaffna. Auto-collected 2026-10-14 (news); review. | M26: https://news.google.com/rss/articles/CBMirwFBVV95cUxOcjFjTFg2ZzhVRzlEakRZekNFeXQzR2ZuQUdDcXFNdG9rQ2JoV2RaYzNnOF9La29FX3BnZXRvY3d3SnlCakNhQVg1dVJ3WnVkT3BwYWZYTnlTdTVoOXBlVDJKc3ZMbmo0bEhmM1pkUGRfdHk2NmEwVFpUNkE3c1FOQl9qVXdEa0JiSXQwWmJvek91dVN0Y0M5NGwxQkQtUDQxLXFib25oWkdNWnlNOGJV?oc=5
A27: NW-0026 | B27: 2019 | C27: 2019-03-17 | D27: இலங்கையில் பெருங்கற்காலத்தில் தமிழர்கள் வாழ்ந்த இடம்; அழிந்து வருவதாக மக்கள் கவலை | F27: BBC | G27: News | H27: Tamil | I27: Archaeology / தொல்லியல் | J27: பெருங்கற் | K27: Yes | L27: Google News query: தொல்லியல் இலங்கை தமிழ். Auto-collected 2026-10-14 (news); review. | M27: https://news.google.com/rss/articles/CBMiV0FVX3lxTE81SUxqWmhQSjVTVWh3S1VLZGV2MHAyTjNDOHBDeHhXX0pCZVJjakRFSnRZQWtxRXdLS2lwakp5eGNiZC1RbGxRUVFrMWpfRDc1VnNSZUFSc9IBXEFVX3lxTFBNa3dMSUJMS0hJVEhnNXZpTzB3b2RFWWhhNDJhN0JDdTFsOU13bVVJZ2RfdUNPVkItQUlHcm9sTEF6NE4xckhmd3gyZVlQTlFTaTQ5NXBfWUx3MnlH?oc=5
A28: NW-0027 | B28: 2019 | C28: 2019-05-30 | D28: 30.05.19 SL Archaeology Dept steps up controversial construction work in Trincomalee | F28: TamilNet | G28: News | H28: English | I28: Archaeology / தொல்லியல் | J28: archaeology | K28: Yes | L28: Google News query: archaeology Vanni Tamil. Auto-collected 2026-10-14 (news); review. | M28: https://news.google.com/rss/articles/CBMiZEFVX3lxTFBaOXhuY19ZUk1ySExJdXFObDBJWDEzMmtqZVhLNTNoNVhhZWhvQm1Idy1uUWRiU1h2Nkg4UWRMTmtNLVhOWU0zSzdBWFZjdzEwQnJtX0FLd1FnWXlpYVl0TU9OSG0?oc=5
A29: NW-0028 | B29: 2019 | C29: 2019-08-19 | D29: Tamil archaeological site under threat from granite mining | F29: Tamil Guardian | G29: News | H29: English | I29: Archaeology / தொல்லியல் | J29: archaeological | K29: Yes | L29: Google News query: archaeology Vanni Tamil. Auto-collected 2026-10-14 (news); review. | M29: https://news.google.com/rss/articles/CBMilgFBVV95cUxPWjg3MzRjZlBYMTRYN2tEcGc5VXRTM25lZTlxYXl1RnhwLTdRQlRxYURPNE1oSGt0VFMxQ2pvNEg1LURmdF9rZ1NhZUNUU2lmSHIyMFpQTFU4cXAxTjZhN3Jsd2FhajVVdjN1dS1zUmptcFNJU0t1dlREZVRTbHAzV1JsTDM4dk9TLXQ2S0dIa3BBVzNnTnc?oc=5
A30: NW-0029 | B30: 2019 | C30: 2019-09-30 | D30: Monument to Tamil king in disrepair as Sri Lanka’s archaeology department ignores destruction | F30: Tamil Guardian | G30: News | H30: English | I30: Archaeology / தொல்லியல் | J30: archaeology | K30: Yes | L30: Google News query: archaeology Vanni Tamil. Auto-collected 2026-10-14 (news); review. | M30: https://news.google.com/rss/articles/CBMivgFBVV95cUxORWRSQ0xORzJLQ2RoNE9KNWhjRnlENktmc2RIZk1VcXIwaWlLZTUwb09YcG1Pc3d2Yk00M0o5cWVsUUV5RmlhajdNeHJaS1dNZmcwUFU1SFh1TEVVbzF4Q0w5R2NvVjZzR1gwbWxIWXNadWlVNHloMUFzdW1yemNIdHE3WWlWbGNUNkpwVUFiTGU3RUJHZ2J1NHFmd2haakE3cGc0T21JMHU2T05TQWkzNWg2NzFkV0hmcWRJVWxn?oc=5
A31: NW-0030 | B31: 2019 | C31: 2019-10-01 | D31: பல ஆண்டுகளுக்குப் பின் தம்பலகாமத்தில் கண்டுபிடிக்கப்பட்ட அரிய தமிழ்க்கல்வெட்டு | F31: Virakesari | G31: News | H31: Tamil | I31: Inscriptions / கல்வெட்டு | J31: கல்வெட்டு | K31: Yes | L31: Google News query: கல்வெட்டு இலங்கை. Auto-collected 2026-10-14 (news); review. | M31: https://news.google.com/rss/articles/CBMiUEFVX3lxTFBoclkwMTRjdmdKLWZ2aVE4Tk5VNUd5VlAyeVM4WG5EVHBNUFFfT2lwTkVweC1qLTJNODhBRE1wdUcxdVpvU3NVXzJFeGFKMXFp?oc=5
A32: NW-0031 | B32: 2018 | C32: 2018-02-11 | D32: Head to the East for a feast of archaeological sites | F32: Sunday Times (Sri Lanka) | G32: Feature | H32: English | I32: Archaeology / தொல்லியல் | J32: archaeology; Eastern Province | K32: Yes | M32: https://www.sundaytimes.lk/180211/plus/head-to-the-east-for-a-feast-of-archaeological-sites-281129.html
A33: NW-0032 | B33: 2018 | C33: 2018-08-16 | D33: New Delhi with ‘cultural presence’ not concerned about Chinese ‘heritage archaeology’ in Kayts | F33: TamilNet | G33: News | H33: English | I33: Archaeology / தொல்லியல் | J33: archaeology | K33: Yes | L33: Google News query: archaeology Jaffna. Auto-collected 2026-10-14 (news); review. | M33: https://news.google.com/rss/articles/CBMiZEFVX3lxTE1OS2ZQSnVTU3JtZVR3Umthby1VWWZYdU1yakJCUExKQ0IzVG56Vm1JRDZDWkF2YV9waVZzWnowWWtkbjFxSWJMVlVSN01SRUtXeTdjNl9YQ0NlZloxUzU0N1ljeVQ?oc=5
A34: NW-0033 | B34: 2018 | C34: 2018-09-15 | D34: China and Sri Lanka unite in Maritime Silk Road archaeological research | F34: CGTN | G34: News | H34: English | I34: Archaeology / தொல்லியல் | J34: archaeological | K34: Yes | L34: Google News query: archaeology Jaffna. Auto-collected 2026-10-14 (news); review. | M34: https://news.google.com/rss/articles/CBMiekFVX3lxTE1nWlpPYTI1SEhvalJHYk9hYlBjX09Ib2hFNVlaTWxEcGhjS25hTnZuWm9uaDdic2U0cHZyQ2RITWpkSTBTRHdCZ25jeTFlSkF0WFdCb2dENmgwLXdvRDZKRlB0c1lhQWxvX1VxdTVSSTdvM0E2TW93WllB0gF_QVVfeXFMT1dFYWh0UEZ3NmR3dC04MUpNZGVvaFp4Q2oyZndXaHlEeHVlV3Y4dWJRWEN0WW1nTmpZZ2pnLVM3VXU2dW5SY2NLamNFcUFNZmVsdXk3U2czUzN2bjlfMk9oaUhDUWhvaTVYdmQ3bUxKMll6dWRBRGFHOE9odGgydw?oc=5
A35: NW-0034 | B35: 2017 | C35: 2017-01-04 | D35: Standing the test of time | F35: Daily News (Sri Lanka) | G35: Feature | H35: English | I35: Archaeology / தொல்லியல் | J35: archaeology | K35: Yes | L35: Relevance to verify | M35: https://archives1.dailynews.lk/2017/01/04/features/103659
A36: NW-0035 | B36: 2017 | C36: 2017-12-20 | D36: Sri Lankan troops in Jaffna lectured on ‘archaeology’ | F36: Tamil Guardian | G36: News | H36: English | I36: Archaeology / தொல்லியல் | J36: archaeology | K36: Yes | L36: Google News query: archaeology Jaffna. Auto-collected 2026-10-14 (news); review. | M36: https://news.google.com/rss/articles/CBMiiwFBVV95cUxPcWJrT2RRWFB4dzZmS1RJY0FoOFZoQzY1ZWJsM0kzZGc4ZlNtZDZIVzBFYVdxdlZsbXNVeF9xOGJqLWh3d0xCNnIxRm5TV2d5RFN0QWJ1ZFJCazdrM1hlVmRXNHBub0pCdHd6Wk1LcTFnY3dydi1xd0J0dUxUNThpZVdnTjJGOUZHVXhF?oc=5
A37: NW-0036 | B37: 2014 | C37: 2014-06-06 | D37: 06.06.14 SL Army conducts ‘archaeology’, The Hindu relays ‘history’ | F37: TamilNet | G37: News | H37: English | I37: Archaeology / தொல்லியல் | J37: archaeology | K37: Yes | L37: Google News query: archaeology Jaffna. Auto-collected 2026-10-14 (news); review. | M37: https://news.google.com/rss/articles/CBMiZEFVX3lxTE1LRUlucXZoVEVIaGlNTU1tN3BjNmpYdGQ3eVhfeTJVb1JMTGhWMndLQVhWTl9VOUZrSm92Z3NFak5OQ05rdGdLLTN2SFNaR0tkT21zVHV0NTdncGN2QmVyT1YyVnA?oc=5
A38: NW-0037 | B38: 2014 | C38: 2014-09-21 | D38: A visit marked in stone | E38: Vinusha Paulraj, Purnima Pilapitiya | F38: Sunday Times (Sri Lanka) | G38: Feature | H38: English | I38: Inscriptions / கல்வெட்டு | J38: Galle trilingual inscription; Tamil | K38: Yes | M38: https://www.sundaytimes.lk/140921/plus/a-visit-marked-in-stone-118621.html
A39: NW-0038 | B39: 2013 | C39: 2013-03-10 | D39: (Rock painting feature) | F39: Sunday Observer | G39: Feature | H39: English | I39: Rock art / பாறை ஓவியம் | J39: rock paintings | K39: Yes | L39: Title to verify | M39: https://archives.sundayobserver.lk/2013/03/10/mon13.asp
A40: NW-0039 | B40: 2013 | C40: 2013-07-27 | D40: Sinhala archaeology focuses operation in North-East corridor | F40: TamilNet | G40: News | H40: English | I40: Archaeology / தொல்லியல் | J40: archaeology; North-East | K40: Yes | M40: https://www.tamilnet.com/art.html?artid=36503&catid=79
A41: NW-0040 | B41: 2013 | C41: 2013-09-13 | D41: 13.09.13 Sri Lanka archaeology claims finding ‘Sinhala Prakrit’ in Delft | F41: TamilNet | G41: News | H41: English | I41: Archaeology / தொல்லியல் | J41: archaeology | K41: Yes | L41: Google News query: Tamil inscription Sri Lanka. Auto-collected 2026-10-14 (news); review. | M41: https://news.google.com/rss/articles/CBMiZEFVX3lxTE9kekJTQWdVczhfMzVmbF9ETVpFUHFGbEw2Mk5LR2JoSXFEelNqZEE5TmJ2VkhubTZJcnJKeE1MLUNTeTdGZFkwbkJQU3dwLTBRSkluenBvbnJraDk3cHN3aER3SW8?oc=5
A42: NW-0041 | B42: 2012 | C42: 2012-10-30 | D42: Tamil went to Oman 20 centuries ago | F42: TamilNet | G42: News | H42: English | I42: Brahmi / பிராமி | J42: Tamil Brahmi; overseas | K42: Yes | M42: https://tamilnet.com/art.html?artid=35707&catid=79
A43: NW-0042 | B43: 2011 | D43: Would the heritage monuments which characterize our culture be considered during road development? | E43: S. Sajitharan | F43: Sunday Yarl Thinakkural | G43: Feature | H43: Tamil | I43: Archaeology / தொல்லியல் | J43: heritage; monuments | K43: Yes | M43: https://www.his.jfn.ac.lk/?p=791
...

Sheet Magazines & Journals
A1: ID | B1: Year | C1: Date | D1: Title | E1: Author / Editor | F1: Publisher / Source | G1: Type | H1: Language | I1: Themes | J1: Keywords | K1: Within 1996-2026 | L1: Notes | M1: URL
A2: MG-0001 | B2: 2026 | C2: 2026-01-09 | D2: மாந்தை: பண்டைய இலங்கையின் நெடுங்கடல் வர்த்தகத் துறைநகர் | E2: Siva Thiagarajah | F2: Ezhuna (எழுநா) | G2: Online magazine article | H2: Tamil | I2: Archaeology / தொல்லியல் | J2: தொல்லியல்; Mantai; port | K2: Yes | L2: Series: Kantarodai civilization of ancient Jaffna | M2: https://www.ezhunaonline.com/manthai-the-seafaring-trading-center-of-ancient-sri-lanka/
A3: MG-0002 | B3: 2026 | C3: 2026-02-09 | D3: மரபிலிருந்து மாறி மரபாகுதல்: யாழ்ப்பாணத்துத் தென்மோடிக் கூத்து | E3: சின்னையா மௌனகுரு | F3: Ezhuna (எழுநா) | G3: Online magazine article | H3: Tamil | K3: Yes | L3: Auto-collected 2026-10-14 (ezhuna); review. | M3: https://www.ezhunaonline.com/from-tradition-to-tradition-the-southern-modic-koothu-of-jaffna/
A4: MG-0003 | B4: 2026 | C4: 2026-02-12 | D4: பண்டைய யாழ்ப்பாணத்தில் புராதன சமய நடைமுறைகள் – பகுதி 2 | E4: Siva Thiagarajah | F4: Ezhuna (எழுநா) | G4: Online magazine article | H4: Tamil | J4: religion; Jaffna | K4: Yes | L4: Series: Kantarodai civilization of ancient Jaffna | M4: https://www.ezhunaonline.com/ancient-religious-practices-in-ancient-jaffna-part-2/
A5: MG-0004 | B5: 2026 | C5: 2026-03-13 | D5: யாழ்ப்பாண பௌத்தம் கி.மு. 100 – கி.பி. 1200 – பகுதி 2 | E5: Siva Thiagarajah | F5: Ezhuna (எழுநா) | G5: Online magazine article | H5: Tamil | I5: Archaeology / தொல்லியல் | J5: Buddhism; Jaffna; archaeology | K5: Yes | L5: Series: Kantarodai civilization of ancient Jaffna | M5: https://www.ezhunaonline.com/jaffna-buddhism-100-bc-1200-ad-part-2/
